package com.trkkr.trkkrclean.architecture

import com.trkkr.trkkrclean.api.ApiResult
import com.trkkr.trkkrclean.api.NetworkErrors.NETWORK_ERROR_TIMEOUT
import com.trkkr.trkkrclean.api.NetworkErrors.NETWORK_ERROR_UNKNOWN
import com.trkkr.trkkrclean.cache.CacheErrors.CACHE_ERROR_TIMEOUT
import com.trkkr.trkkrclean.cache.CacheErrors.CACHE_ERROR_UNKNOWN
import com.trkkr.trkkrclean.cache.CacheResult
import kotlinx.coroutines.CoroutineDispatcher
import kotlinx.coroutines.TimeoutCancellationException
import kotlinx.coroutines.withContext
import kotlinx.coroutines.withTimeout
import retrofit2.HttpException
import java.io.IOException

/**
 * Reference: https://medium.com/@douglas.iacovelli/how-to-handle-errors-with-retrofit-and-coroutines-33e7492a912
 */
const val NETWORK_TIMEOUT = 6000L
const val CACHE_TIMEOUT = 2000L
const val ERROR_UNKNOWN = "Unknown error"

suspend fun <T> safeApiCall(
    dispatcher: CoroutineDispatcher,
    apiCall: suspend () -> T?
): ApiResult<T?> {
    return withContext(dispatcher) {
        try {
            // throws TimeoutCancellationException
            withTimeout(NETWORK_TIMEOUT){
                ApiResult.Success(apiCall.invoke())
            }
        } catch (throwable: Throwable) {
            throwable.printStackTrace()
            when (throwable) {
                is TimeoutCancellationException -> {
                    val code = 408 // timeout error code
                    ApiResult.GenericError(code, NETWORK_ERROR_TIMEOUT)
                }
                is IOException -> {
                    ApiResult.NetworkError
                }
                is HttpException -> {
                    val code = throwable.code()
                    val errorResponse = convertErrorBody(throwable)
                    //cLog(errorResponse)
                    ApiResult.GenericError(
                        code,
                        errorResponse
                    )
                }
                else -> {
                    //cLog(NETWORK_ERROR_UNKNOWN)
                    ApiResult.GenericError(
                        null,
                        NETWORK_ERROR_UNKNOWN
                    )
                }
            }
        }
    }
}

suspend fun <T> safeCacheCall(
    dispatcher: CoroutineDispatcher,
    cacheCall: suspend () -> T?
): CacheResult<T?> {
    return withContext(dispatcher) {
        try {
            // throws TimeoutCancellationException
            withTimeout(CACHE_TIMEOUT){
                CacheResult.Success(cacheCall.invoke())
            }
        } catch (throwable: Throwable) {
            throwable.printStackTrace()
            when (throwable) {

                is TimeoutCancellationException -> {
                    CacheResult.GenericError(CACHE_ERROR_TIMEOUT)
                }
                else -> {
                    //cLog(CACHE_ERROR_UNKNOWN)
                    CacheResult.GenericError(CACHE_ERROR_UNKNOWN)
                }
            }
        }
    }
}


private fun convertErrorBody(throwable: HttpException): String? {
    return try {
        throwable.response()?.errorBody()?.string()
    } catch (exception: Exception) {
        ERROR_UNKNOWN
    }
}